Workbook
Name Slicer_Customer_Type: #N/A
Name Slicer_Region: #N/A
Name Slicer_Status: #N/A

Sheet Data
A1: Project ID | B1: Project Name | C1: Region | D1: City | E1: Customer Type | F1: Project Value (₹ Lakhs) | G1: Start Date | H1: Planned Completion | I1: Actual Completion | J1: Delay (Days) | K1: Installation Stage | L1: Status | M1: Handover Status | N1: Delay Status | P1: Checking Duplicte | Q1: Blank Value
A2: PRJ001 | B2: Skyline Residency | C2: Central Kerala | D2: Kochi | E2: Residential | F2: 18 | G2: 46024 | H2: 46127 | I2: 46124 | J2: =IF(I2="","",I2-H2) -> -3 | K2: Handover | L2: Completed | M2: Completed | N2: =IF(I2="","In Progress",IF(J2>0,"Delayed",IF(J2=0,"On Time","Early"))) -> Early | O2: =COUNTIF(A2:A306,A2) -> 1 | P2: =COUNTIF($A$2:$A$306,A2) -> 1 | Q2: =COUNTBLANK(A2:A306) -> 0 | R2: A2 to A306
A3: PRJ002 | B3: Green Valley Apartments | C3: Central Kerala | D3: Kochi | E3: Apartment | F3: 24 | G3: 46032 | H3: 46167 | I3: 46172 | J3: =IF(I3="","",I3-H3) -> 5 | K3: Handover | L3: Completed | M3: Completed | N3: =IF(I3="","In Progress",IF(J3>0,"Delayed",IF(J3=0,"On Time","Early"))) -> Delayed | P3: =COUNTIF($A$2:$A$306,A3) -> 1 | Q3: =COUNTBLANK(A2:A307) -> 1 | R3: A2 to A307
A4: PRJ003 | B4: Orchid Hospital | C4: South Kerala | D4: Trivandrum | E4: Hospital | F4: 42 | G4: 46040 | H4: 46203 | I4: 46201 | J4: =IF(I4="","",I4-H4) -> -2 | K4: Handover | L4: Completed | M4: Completed | N4: =IF(I4="","In Progress",IF(J4>0,"Delayed",IF(J4=0,"On Time","Early"))) -> Early | P4: =COUNTIF($A$2:$A$306,A4) -> 1
A5: PRJ004 | B5: Metro Business Park | C5: Central Kerala | D5: Kochi | E5: Office | F5: 65 | G5: 46054 | H5: 46233 | J5: =IF(I5="","",I5-H5) | K5: Installation Started | L5: In Progress | M5: Pending | N5: =IF(I5="","In Progress",IF(J5>0,"Delayed",IF(J5=0,"On Time","Early"))) -> In Progress | P5: =COUNTIF($A$2:$A$306,A5) -> 1
A6: PRJ005 | B6: Grand Palace Hotel | C6: Central Kerala | D6: Thrissur | E6: Hotel | F6: 38 | G6: 46061 | H6: 46188 | I6: 46195 | J6: =IF(I6="","",I6-H6) -> 7 | K6: Handover | L6: Completed | M6: Completed | N6: =IF(I6="","In Progress",IF(J6>0,"Delayed",IF(J6=0,"On Time","Early"))) -> Delayed | P6: =COUNTIF($A$2:$A$306,A6) -> 1
A7: PRJ006 | B7: City Centre Mall | C7: Central Kerala | D7: Kochi | E7: Shopping Mall | F7: 55 | G7: 46068 | H7: 46264 | J7: =IF(I7="","",I7-H7) | K7: Material Delivered | L7: In Progress | M7: Pending | N7: =IF(I7="","In Progress",IF(J7>0,"Delayed",IF(J7=0,"On Time","Early"))) -> In Progress | O7: =COUNTIFS(tbl_ProjectData[Region],"North Kerala",tbl_ProjectData[Status],"Completed",tbl_ProjectData[Delay Status],"Delayed") -> 1 | P7: =COUNTIF($A$2:$A$306,A7) -> 1
A8: PRJ007 | B8: Harmony Heights | C8: South Kerala | D8: Kollam | E8: Residential | F8: 27 | G8: 46042 | H8: 46162 | I8: 46160 | J8: =IF(I8="","",I8-H8) -> -2 | K8: Handover | L8: Completed | M8: Completed | N8: =IF(I8="","In Progress",IF(J8>0,"Delayed",IF(J8=0,"On Time","Early"))) -> Early | P8: =COUNTIF($A$2:$A$306,A8) -> 1
A9: PRJ008 | B9: River View Residency | C9: North Kerala | D9: Kozhikode | E9: Residential | F9: 21 | G9: 46086 | H9: 46203 | I9: 46208 | J9: =IF(I9="","",I9-H9) -> 5 | K9: Handover | L9: Completed | M9: Completed | N9: =IF(I9="","In Progress",IF(J9>0,"Delayed",IF(J9=0,"On Time","Early"))) -> Delayed | P9: =COUNTIF($A$2:$A$306,A9) -> 1
A10: PRJ009 | B10: Tech Square Offices | C10: Central Kerala | D10: Kochi | E10: Office | F10: 48 | G10: 46065 | H10: 46218 | I10: 46217 | J10: =IF(I10="","",I10-H10) -> -1 | K10: Handover | L10: Completed | M10: Completed | N10: =IF(I10="","In Progress",IF(J10>0,"Delayed",IF(J10=0,"On Time","Early"))) -> Early | P10: =COUNTIF($A$2:$A$306,A10) -> 1
A11: PRJ010 | B11: Sunrise Towers | C11: North Kerala | D11: Kannur | E11: Commercial | F11: 32 | G11: 46113 | H11: 46295 | J11: =IF(I11="","",I11-H11) | K11: Material Ordered | L11: In Progress | M11: Pending | N11: =IF(I11="","In Progress",IF(J11>0,"Delayed",IF(J11=0,"On Time","Early"))) -> In Progress | P11: =COUNTIF($A$2:$A$306,A11) -> 1 | R11: =COUNTIF(L2:L306,"Completed") -> 58 | S11: Completed
A12: ="PRJ"&TEXT(ROW()-1,"000") -> PRJ011 | B12: =CHOOSE(MOD(ROW()-2,10)+1,"Green Valley","Royal Palm","Skyline","Harmony","Lakeside","Sunrise","Silver Oak","River View","Golden Gate","Emerald")&" "&CHOOSE(MOD(INT((ROW()-2)/10),8)+1,"Residency","Apartments","Heights","Towers","Enclave","Business Centre","Grand Hotel","Care Hospital")&" "&TEXT(ROW()-1,"000") -> Green Valley Apartments 011 | C12: =CHOOSE(MOD(ROW()-2,3)+1,"North Kerala","Central Kerala","South Kerala") -> Central Kerala | D12: =IF(C12="North Kerala",CHOOSE(MOD(ROW()-2,4)+1,"Kannur","Kozhikode","Wayanad","Kasaragod"),IF(C12="Central Kerala",CHOOSE(MOD(ROW()-2,6)+1,"Kochi","Thrissur","Kottayam","Palakkad","Idukki","Alappuzha"),CHOOSE(MOD(ROW()-2,4)+1,"Trivandrum","Kollam","Pathanamthitta","Alappuzha"))) -> Idukki | E12: =CHOOSE(MOD(ROW()-2,6)+1,"Residential","Apartment","Hospital","Office","Hotel","Commercial") -> Hotel | F12: =CHOOSE(MOD(ROW()-2,10)+1,18,24,42,65,38,55,27,21,48,32) -> 18 | G12: =DATE(2026,1,1)+MOD((ROW()-12)*7,180) -> 46023 | H12: =G12+CHOOSE(MOD(ROW()-2,5)+1,90,120,150,180,210) -> 46113 | I12: =IF(MOD(ROW()-2,4)=0,"",H12+CHOOSE(MOD(ROW()-2,5)+1,-5,0,7,-2,10)) -> 46108 | J12: =IF(I12="","",I12-H12) -> -5 | K12: =CHOOSE(MOD(ROW()-2,6)+1,"Material Ordered","Material Delivered","Installation Started","Mechanical Completion","Testing & Commissioning","Handover") -> Testing & Commissioning | L12: =IF(K12="Handover","Completed","In Progress") -> In Progress | M12: =IF(K12="Handover","Completed","Pending") -> Pending | N12: =IF(I12="","In Progress",IF(J12>0,"Delayed",IF(J12=0,"On Time","Early"))) -> Early | P12: =COUNTIF($A$2:$A$306,A12) -> 1 | R12: =COUNTIF(L2:L306,"In Progress") -> 247 | S12: In Progress
A13: ="PRJ"&TEXT(ROW()-1,"000") -> PRJ012 | B13: =CHOOSE(MOD(ROW()-2,10)+1,"Green Valley","Royal Palm","Skyline","Harmony","Lakeside","Sunrise","Silver Oak","River View","Golden Gate","Emerald")&" "&CHOOSE(MOD(INT((ROW()-2)/10),8)+1,"Residency","Apartments","Heights","Towers","Enclave","Business Centre","Grand Hotel","Care Hospital")&" "&TEXT(ROW()-1,"000") -> Royal Palm Apartments 012 | C13: =CHOOSE(MOD(ROW()-2,3)+1,"North Kerala","Central Kerala","South Kerala") -> South Kerala | D13: =IF(C13="North Kerala",CHOOSE(MOD(ROW()-2,4)+1,"Kannur","Kozhikode","Wayanad","Kasaragod"),IF(C13="Central Kerala",CHOOSE(MOD(ROW()-2,6)+1,"Kochi","Thrissur","Kottayam","Palakkad","Idukki","Alappuzha"),CHOOSE(MOD(ROW()-2,4)+1,"Trivandrum","Kollam","Pathanamthitta","Alappuzha"))) -> Alappuzha | E13: =CHOOSE(MOD(ROW()-2,6)+1,"Residential","Apartment","Hospital","Office","Hotel","Commercial") -> Commercial | F13: =CHOOSE(MOD(ROW()-2,10)+1,18,24,42,65,38,55,27,21,48,32) -> 24 | G13: =DATE(2026,1,1)+MOD((ROW()-12)*7,180) -> 46030 | H13: =G13+CHOOSE(MOD(ROW()-2,5)+1,90,120,150,180,210) -> 46150 | I13: =IF(MOD(ROW()-2,4)=0,"",H13+CHOOSE(MOD(ROW()-2,5)+1,-5,0,7,-2,10)) -> 46150 | J13: =IF(I13="","",I13-H13) -> 0 | K13: =CHOOSE(MOD(ROW()-2,6)+1,"Material Ordered","Material Delivered","Installation Started","Mechanical Completion","Testing & Commissioning","Handover") -> Handover | L13: =IF(K13="Handover","Completed","In Progress") -> Completed | M13: =IF(K13="Handover","Completed","Pending") -> Completed | N13: =IF(I13="","In Progress",IF(J13>0,"Delayed",IF(J13=0,"On Time","Early"))) -> On Time | P13: =COUNTIF($A$2:$A$306,A13) -> 1 | R13: =COUNTIF(E2:E306,"Hospital") -> 50 | S13: Customer Type - Hospital
A14: ="PRJ"&TEXT(ROW()-1,"000") -> PRJ013 | B14: =CHOOSE(MOD(ROW()-2,10)+1,"Green Valley","Royal Palm","Skyline","Harmony","Lakeside","Sunrise","Silver Oak","River View","Golden Gate","Emerald")&" "&CHOOSE(MOD(INT((ROW()-2)/10),8)+1,"Residency","Apartments","Heights","Towers","Enclave","Business Centre","Grand Hotel","Care Hospital")&" "&TEXT(ROW()-1,"000") -> Skyline Apartments 013 | C14: =CHOOSE(MOD(ROW()-2,3)+1,"North Kerala","Central Kerala","South Kerala") -> North Kerala | D14: =IF(C14="North Kerala",CHOOSE(MOD(ROW()-2,4)+1,"Kannur","Kozhikode","Wayanad","Kasaragod"),IF(C14="Central Kerala",CHOOSE(MOD(ROW()-2,6)+1,"Kochi","Thrissur","Kottayam","Palakkad","Idukki","Alappuzha"),CHOOSE(MOD(ROW()-2,4)+1,"Trivandrum","Kollam","Pathanamthitta","Alappuzha"))) -> Kannur | E14: =CHOOSE(MOD(ROW()-2,6)+1,"Residential","Apartment","Hospital","Office","Hotel","Commercial") -> Residential | F14: =CHOOSE(MOD(ROW()-2,10)+1,18,24,42,65,38,55,27,21,48,32) -> 42 | G14: =DATE(2026,1,1)+MOD((ROW()-12)*7,180) -> 46037 | H14: =G14+CHOOSE(MOD(ROW()-2,5)+1,90,120,150,180,210) -> 46187 | I14: =IF(MOD(ROW()-2,4)=0,"",H14+CHOOSE(MOD(ROW()-2,5)+1,-5,0,7,-2,10)) | J14: =IF(I14="","",I14-H14) | K14: =CHOOSE(MOD(ROW()-2,6)+1,"Material Ordered","Material Delivered","Installation Started","Mechanical Completion","Testing & Commissioning","Handover") -> Material Ordered | L14: =IF(K14="Handover","Completed","In Progress") -> In Progress | M14: =IF(K14="Handover","Completed","Pending") -> Pending | N14: =IF(I14="","In Progress",IF(J14>0,"Delayed",IF(J14=0,"On Time","Early"))) -> In Progress | P14: =COUNTIF($A$2:$A$306,A14) -> 1 | R14: =COUNTA(E2:E306) -> 305
A15: ="PRJ"&TEXT(ROW()-1,"000") -> PRJ014 | B15: =CHOOSE(MOD(ROW()-2,10)+1,"Green Valley","Royal Palm","Skyline","Harmony","Lakeside","Sunrise","Silver Oak","River View","Golden Gate","Emerald")&" "&CHOOSE(MOD(INT((ROW()-2)/10),8)+1,"Residency","Apartments","Heights","Towers","Enclave","Business Centre","Grand Hotel","Care Hospital")&" "&TEXT(ROW()-1,"000") -> Harmony Apartments 014 | C15: =CHOOSE(MOD(ROW()-2,3)+1,"North Kerala","Central Kerala","South Kerala") -> Central Kerala | D15: =IF(C15="North Kerala",CHOOSE(MOD(ROW()-2,4)+1,"Kannur","Kozhikode","Wayanad","Kasaragod"),IF(C15="Central Kerala",CHOOSE(MOD(ROW()-2,6)+1,"Kochi","Thrissur","Kottayam","Palakkad","Idukki","Alappuzha"),CHOOSE(MOD(ROW()-2,4)+1,"Trivandrum","Kollam","Pathanamthitta","Alappuzha"))) -> Thrissur | E15: =CHOOSE(MOD(ROW()-2,6)+1,"Residential","Apartment","Hospital","Office","Hotel","Commercial") -> Apartment | F15: =CHOOSE(MOD(ROW()-2,10)+1,18,24,42,65,38,55,27,21,48,32) -> 65 | G15: =DATE(2026,1,1)+MOD((ROW()-12)*7,180) -> 46044 | H15: =G15+CHOOSE(MOD(ROW()-2,5)+1,90,120,150,180,210) -> 46224 | I15: =IF(MOD(ROW()-2,4)=0,"",H15+CHOOSE(MOD(ROW()-2,5)+1,-5,0,7,-2,10)) -> 46222 | J15: =IF(I15="","",I15-H15) -> -2 | K15: =CHOOSE(MOD(ROW()-2,6)+1,"Material Ordered","Material Delivered","Installation Started","Mechanical Completion","Testing & Commissioning","Handover") -> Material Delivered | L15: =IF(K15="Handover","Completed","In Progress") -> In Progress | M15: =IF(K15="Handover","Completed","Pending") -> Pending | N15: =IF(I15="","In Progress",IF(J15>0,"Delayed",IF(J15=0,"On Time","Early"))) -> Early | P15: =COUNTIF($A$2:$A$306,A15) -> 1 | R15: =COUNTBLANK(A2:A306) -> 0
A16: ="PRJ"&TEXT(ROW()-1,"000") -> PRJ015 | B16: =CHOOSE(MOD(ROW()-2,10)+1,"Green Valley","Royal Palm","Skyline","Harmony","Lakeside","Sunrise","Silver Oak","River View","Golden Gate","Emerald")&" "&CHOOSE(MOD(INT((ROW()-2)/10),8)+1,"Residency","Apartments","Heights","Towers","Enclave","Business Centre","Grand Hotel","Care Hospital")&" "&TEXT(ROW()-1,"000") -> Lakeside Apartments 015 | C16: =CHOOSE(MOD(ROW()-2,3)+1,"North Kerala","Central Kerala","South Kerala") -> South Kerala | D16: =IF(C16="North Kerala",CHOOSE(MOD(ROW()-2,4)+1,"Kannur","Kozhikode","Wayanad","Kasaragod"),IF(C16="Central Kerala",CHOOSE(MOD(ROW()-2,6)+1,"Kochi","Thrissur","Kottayam","Palakkad","Idukki","Alappuzha"),CHOOSE(MOD(ROW()-2,4)+1,"Trivandrum","Kollam","Pathanamthitta","Alappuzha"))) -> Pathanamthitta | E16: =CHOOSE(MOD(ROW()-2,6)+1,"Residential","Apartment","Hospital","Office","Hotel","Commercial") -> Hospital | F16: =CHOOSE(MOD(ROW()-2,10)+1,18,24,42,65,38,55,27,21,48,32) -> 38 | G16: =DATE(2026,1,1)+MOD((ROW()-12)*7,180) -> 46051 | H16: =G16+CHOOSE(MOD(ROW()-2,5)+1,90,120,150,180,210) -> 46261 | I16: =IF(MOD(ROW()-2,4)=0,"",H16+CHOOSE(MOD(ROW()-2,5)+1,-5,0,7,-2,10)) -> 46271 | J16: =IF(I16="","",I16-H16) -> 10 | K16: =CHOOSE(MOD(ROW()-2,6)+1,"Material Ordered","Material Delivered","Installation Started","Mechanical Completion","Testing & Commissioning","Handover") -> Installation Started | L16: =IF(K16="Handover","Completed","In Progress") -> In Progress | M16: =IF(K16="Handover","Completed","Pending") -> Pending | N16: =IF(I16="","In Progress",IF(J16>0,"Delayed",IF(J16=0,"On Time","Early"))) -> Delayed | P16: =COUNTIF($A$2:$A$306,A16) -> 1 | R16: =COUNTBLANK(L2:L306) -> 0
A17: ="PRJ"&TEXT(ROW()-1,"000") -> PRJ016 | B17: =CHOOSE(MOD(ROW()-2,10)+1,"Green Valley","Royal Palm","Skyline","Harmony","Lakeside","Sunrise","Silver Oak","River View","Golden Gate","Emerald")&" "&CHOOSE(MOD(INT((ROW()-2)/10),8)+1,"Residency","Apartments","Heights","Towers","Enclave","Business Centre","Grand Hotel","Care Hospital")&" "&TEXT(ROW()-1,"000") -> Sunrise Apartments 016 | C17: =CHOOSE(MOD(ROW()-2,3)+1,"North Kerala","Central Kerala","South Kerala") -> North Kerala | D17: =IF(C17="North Kerala",CHOOSE(MOD(ROW()-2,4)+1,"Kannur","Kozhikode","Wayanad","Kasaragod"),IF(C17="Central Kerala",CHOOSE(MOD(ROW()-2,6)+1,"Kochi","Thrissur","Kottayam","Palakkad","Idukki","Alappuzha"),CHOOSE(MOD(ROW()-2,4)+1,"Trivandrum","Kollam","Pathanamthitta","Alappuzha"))) -> Kasaragod | E17: =CHOOSE(MOD(ROW()-2,6)+1,"Residential","Apartment","Hospital","Office","Hotel","Commercial") -> Office | F17: =CHOOSE(MOD(ROW()-2,10)+1,18,24,42,65,38,55,27,21,48,32) -> 55 | G17: =DATE(2026,1,1)+MOD((ROW()-12)*7,180) -> 46058 | H17: =G17+CHOOSE(MOD(ROW()-2,5)+1,90,120,150,180,210) -> 46148 | I17: =IF(MOD(ROW()-2,4)=0,"",H17+CHOOSE(MOD(ROW()-2,5)+1,-5,0,7,-2,10)) -> 46143 | J17: =IF(I17="","",I17-H17) -> -5 | K17: =CHOOSE(MOD(ROW()-2,6)+1,"Material Ordered","Material Delivered","Installation Started","Mechanical Completion","Testing & Commissioning","Handover") -> Mechanical Completion | L17: =IF(K17="Handover","Completed","In Progress") -> In Progress | M17: =IF(K17="Handover","Completed","Pending") -> Pending | N17: =IF(I17="","In Progress",IF(J17>0,"Delayed",IF(J17=0,"On Time","Early"))) -> Early | P17: =COUNTIF($A$2:$A$306,A17) -> 1
A18: ="PRJ"&TEXT(ROW()-1,"000") -> PRJ017 | B18: =CHOOSE(MOD(ROW()-2,10)+1,"Green Valley","Royal Palm","Skyline","Harmony","Lakeside","Sunrise","Silver Oak","River View","Golden Gate","Emerald")&" "&CHOOSE(MOD(INT((ROW()-2)/10),8)+1,"Residency","Apartments","Heights","Towers","Enclave","Business Centre","Grand Hotel","Care Hospital")&" "&TEXT(ROW()-1,"000") -> Silver Oak Apartments 017 | C18: =CHOOSE(MOD(ROW()-2,3)+1,"North Kerala","Central Kerala","South Kerala") -> Central Kerala | D18: =IF(C18="North Kerala",CHOOSE(MOD(ROW()-2,4)+1,"Kannur","Kozhikode","Wayanad","Kasaragod"),IF(C18="Central Kerala",CHOOSE(MOD(ROW()-2,6)+1,"Kochi","Thrissur","Kottayam","Palakkad","Idukki","Alappuzha"),CHOOSE(MOD(ROW()-2,4)+1,"Trivandrum","Kollam","Pathanamthitta","Alappuzha"))) -> Idukki | E18: =CHOOSE(MOD(ROW()-2,6)+1,"Residential","Apartment","Hospital","Office","Hotel","Commercial") -> Hotel | F18: =CHOOSE(MOD(ROW()-2,10)+1,18,24,42,65,38,55,27,21,48,32) -> 27 | G18: =DATE(2026,1,1)+MOD((ROW()-12)*7,180) -> 46065 | H18: =G18+CHOOSE(MOD(ROW()-2,5)+1,90,120,150,180,210) -> 46185 | I18: =IF(MOD(ROW()-2,4)=0,"",H18+CHOOSE(MOD(ROW()-2,5)+1,-5,0,7,-2,10)) | J18: =IF(I18="","",I18-H18) | K18: =CHOOSE(MOD(ROW()-2,6)+1,"Material Ordered","Material Delivered","Installation Started","Mechanical Completion","Testing & Commissioning","Handover") -> Testing & Commissioning | L18: =IF(K18="Handover","Completed","In Progress") -> In Progress | M18: =IF(K18="Handover","Completed","Pending") -> Pending | N18: =IF(I18="","In Progress",IF(J18>0,"Delayed",IF(J18=0,"On Time","Early"))) -> In Progress | P18: =COUNTIF($A$2:$A$306,A18) -> 1
A19: ="PRJ"&TEXT(ROW()-1,"000") -> PRJ018 | B19: =CHOOSE(MOD(ROW()-2,10)+1,"Green Valley","Royal Palm","Skyline","Harmony","Lakeside","Sunrise","Silver Oak","River View","Golden Gate","Emerald")&" "&CHOOSE(MOD(INT((ROW()-2)/10),8)+1,"Residency","Apartments","Heights","Towers","Enclave","Business Centre","Grand Hotel","Care Hospital")&" "&TEXT(ROW()-1,"000") -> River View Apartments 018 | C19: =CHOOSE(MOD(ROW()-2,3)+1,"North Kerala","Central Kerala","South Kerala") -> South Kerala | D19: =IF(C19="North Kerala",CHOOSE(MOD(ROW()-2,4)+1,"Kannur","Kozhikode","Wayanad","Kasaragod"),IF(C19="Central Kerala",CHOOSE(MOD(ROW()-2,6)+1,"Kochi","Thrissur","Kottayam","Palakkad","Idukki","Alappuzha"),CHOOSE(MOD(ROW()-2,4)+1,"Trivandrum","Kollam","Pathanamthitta","Alappuzha"))) -> Kollam | E19: =CHOOSE(MOD(ROW()-2,6)+1,"Residential","Apartment","Hospital","Office","Hotel","Commercial") -> Commercial | F19: =CHOOSE(MOD(ROW()-2,10)+1,18,24,42,65,38,55,27,21,48,32) -> 21 | G19: =DATE(2026,1,1)+MOD((ROW()-12)*7,180) -> 46072 | H19: =G19+CHOOSE(MOD(ROW()-2,5)+1,90,120,150,180,210) -> 46222 | I19: =IF(MOD(ROW()-2,4)=0,"",H19+CHOOSE(MOD(ROW()-2,5)+1,-5,0,7,-2,10)) -> 46229 | J19: =IF(I19="","",I19-H19) -> 7 | K19: =CHOOSE(MOD(ROW()-2,6)+1,"Material Ordered","Material Delivered","Installation Started","Mechanical Completion","Testing & Commissioning","Handover") -> Handover | L19: =IF(K19="Handover","Completed","In Progress") -> Completed | M19: =IF(K19="Handover","Completed","Pending") -> Completed | N19: =IF(I19="","In Progress",IF(J19>0,"Delayed",IF(J19=0,"On Time","Early"))) -> Delayed | P19: =COUNTIF($A$2:$A$306,A19) -> 1
A20: ="PRJ"&TEXT(ROW()-1,"000") -> PRJ019 | B20: =CHOOSE(MOD(ROW()-2,10)+1,"Green Valley","Royal Palm","Skyline","Harmony","Lakeside","Sunrise","Silver Oak","River View","Golden Gate","Emerald")&" "&CHOOSE(MOD(INT((ROW()-2)/10),8)+1,"Residency","Apartments","Heights","Towers","Enclave","Business Centre","Grand Hotel","Care Hospital")&" "&TEXT(ROW()-1,"000") -> Golden Gate Apartments 019 | C20: =CHOOSE(MOD(ROW()-2,3)+1,"North Kerala","Central Kerala","South Kerala") -> North Kerala | D20: =IF(C20="North Kerala",CHOOSE(MOD(ROW()-2,4)+1,"Kannur","Kozhikode","Wayanad","Kasaragod"),IF(C20="Central Kerala",CHOOSE(MOD(ROW()-2,6)+1,"Kochi","Thrissur","Kottayam","Palakkad","Idukki","Alappuzha"),CHOOSE(MOD(ROW()-2,4)+1,"Trivandrum","Kollam","Pathanamthitta","Alappuzha"))) -> Wayanad | E20: =CHOOSE(MOD(ROW()-2,6)+1,"Residential","Apartment","Hospital","Office","Hotel","Commercial") -> Residential | F20: =CHOOSE(MOD(ROW()-2,10)+1,18,24,42,65,38,55,27,21,48,32) -> 48 | G20: =DATE(2026,1,1)+MOD((ROW()-12)*7,180) -> 46079 | H20: =G20+CHOOSE(MOD(ROW()-2,5)+1,90,120,150,180,210) -> 46259 | I20: =IF(MOD(ROW()-2,4)=0,"",H20+CHOOSE(MOD(ROW()-2,5)+1,-5,0,7,-2,10)) -> 46257 | J20: =IF(I20="","",I20-H20) -> -2 | K20: =CHOOSE(MOD(ROW()-2,6)+1,"Material Ordered","Material Delivered","Installation Started","Mechanical Completion","Testing & Commissioning","Handover") -> Material Ordered | L20: =IF(K20="Handover","Completed","In Progress") -> In Progress | M20: =IF(K20="Handover","Completed","Pending") -> Pending | N20: =IF(I20="","In Progress",IF(J20>0,"Delayed",IF(J20=0,"On Time","Early"))) -> Early | P20: =COUNTIF($A$2:$A$306,A20) -> 1
A21: ="PRJ"&TEXT(ROW()-1,"000") -> PRJ020 | B21: =CHOOSE(MOD(ROW()-2,10)+1,"Green Valley","Royal Palm","Skyline","Harmony","Lakeside","Sunrise","Silver Oak","River View","Golden Gate","Emerald")&" "&CHOOSE(MOD(INT((ROW()-2)/10),8)+1,"Residency","Apartments","Heights","Towers","Enclave","Business Centre","Grand Hotel","Care Hospital")&" "&TEXT(ROW()-1,"000") -> Emerald Apartments 020 | C21: =CHOOSE(MOD(ROW()-2,3)+1,"North Kerala","Central Kerala","South Kerala") -> Central Kerala | D21: =IF(C21="North Kerala",CHOOSE(MOD(ROW()-2,4)+1,"Kannur","Kozhikode","Wayanad","Kasaragod"),IF(C21="Central Kerala",CHOOSE(MOD(ROW()-2,6)+1,"Kochi","Thrissur","Kottayam","Palakkad","Idukki","Alappuzha"),CHOOSE(MOD(ROW()-2,4)+1,"Trivandrum","Kollam","Pathanamthitta","Alappuzha"))) -> Thrissur | E21: =CHOOSE(MOD(ROW()-2,6)+1,"Residential","Apartment","Hospital","Office","Hotel","Commercial") -> Apartment | F21: =CHOOSE(MOD(ROW()-2,10)+1,18,24,42,65,38,55,27,21,48,32) -> 32 | G21: =DATE(2026,1,1)+MOD((ROW()-12)*7,180) -> 46086 | H21: =G21+CHOOSE(MOD(ROW()-2,5)+1,90,120,150,180,210) -> 46296 | I21: =IF(MOD(ROW()-2,4)=0,"",H21+CHOOSE(MOD(ROW()-2,5)+1,-5,0,7,-2,10)) -> 46306 | J21: =IF(I21="","",I21-H21) -> 10 | K21: =CHOOSE(MOD(ROW()-2,6)+1,"Material Ordered","Material Delivered","Installation Started","Mechanical Completion","Testing & Commissioning","Handover") -> Material Delivered | L21: =IF(K21="Handover","Completed","In Progress") -> In Progress | M21: =IF(K21="Handover","Completed","Pending") -> Pending | N21: =IF(I21="","In Progress",IF(J21>0,"Delayed",IF(J21=0,"On Time","Early"))) -> Delayed | P21: =COUNTIF($A$2:$A$306,A21) -> 1
A22: ="PRJ"&TEXT(ROW()-1,"000") -> PRJ021 | B22: =CHOOSE(MOD(ROW()-2,10)+1,"Green Valley","Royal Palm","Skyline","Harmony","Lakeside","Sunrise","Silver Oak","River View","Golden Gate","Emerald")&" "&CHOOSE(MOD(INT((ROW()-2)/10),8)+1,"Residency","Apartments","Heights","Towers","Enclave","Business Centre","Grand Hotel","Care Hospital")&" "&TEXT(ROW()-1,"000") -> Green Valley Heights 021 | C22: =CHOOSE(MOD(ROW()-2,3)+1,"North Kerala","Central Kerala","South Kerala") -> South Kerala | D22: =IF(C22="North Kerala",CHOOSE(MOD(ROW()-2,4)+1,"Kannur","Kozhikode","Wayanad","Kasaragod"),IF(C22="Central Kerala",CHOOSE(MOD(ROW()-2,6)+1,"Kochi","Thrissur","Kottayam","Palakkad","Idukki","Alappuzha"),CHOOSE(MOD(ROW()-2,4)+1,"Trivandrum","Kollam","Pathanamthitta","Alappuzha"))) -> Trivandrum | E22: =CHOOSE(MOD(ROW()-2,6)+1,"Residential","Apartment","Hospital","Office","Hotel","Commercial") -> Hospital | F22: =CHOOSE(MOD(ROW()-2,10)+1,18,24,42,65,38,55,27,21,48,32) -> 18 | G22: =DATE(2026,1,1)+MOD((ROW()-12)*7,180) -> 46093 | H22: =G22+CHOOSE(MOD(ROW()-2,5)+1,90,120,150,180,210) -> 46183 | I22: =IF(MOD(ROW()-2,4)=0,"",H22+CHOOSE(MOD(ROW()-2,5)+1,-5,0,7,-2,10)) | J22: =IF(I22="","",I22-H22) | K22: =CHOOSE(MOD(ROW()-2,6)+1,"Material Ordered","Material Delivered","Installation Started","Mechanical Completion","Testing & Commissioning","Handover") -> Installation Started | L22: =IF(K22="Handover","Completed","In Progress") -> In Progress | M22: =IF(K22="Handover","Completed","Pending") -> Pending | N22: =IF(I22="","In Progress",IF(J22>0,"Delayed",IF(J22=0,"On Time","Early"))) -> In Progress | P22: =COUNTIF($A$2:$A$306,A22) -> 1
A23: ="PRJ"&TEXT(ROW()-1,"000") -> PRJ022 | B23: =CHOOSE(MOD(ROW()-2,10)+1,"Green Valley","Royal Palm","Skyline","Harmony","Lakeside","Sunrise","Silver Oak","River View","Golden Gate","Emerald")&" "&CHOOSE(MOD(INT((ROW()-2)/10),8)+1,"Residency","Apartments","Heights","Towers","Enclave","Business Centre","Grand Hotel","Care Hospital")&" "&TEXT(ROW()-1,"000") -> Royal Palm Heights 022 | C23: =CHOOSE(MOD(ROW()-2,3)+1,"North Kerala","Central Kerala","South Kerala") -> North Kerala | D23: =IF(C23="North Kerala",CHOOSE(MOD(ROW()-2,4)+1,"Kannur","Kozhikode","Wayanad","Kasaragod"),IF(C23="Central Kerala",CHOOSE(MOD(ROW()-2,6)+1,"Kochi","Thrissur","Kottayam","Palakkad","Idukki","Alappuzha"),CHOOSE(MOD(ROW()-2,4)+1,"Trivandrum","Kollam","Pathanamthitta","Alappuzha"))) -> Kozhikode | E23: =CHOOSE(MOD(ROW()-2,6)+1,"Residential","Apartment","Hospital","Office","Hotel","Commercial") -> Office | F23: =CHOOSE(MOD(ROW()-2,10)+1,18,24,42,65,38,55,27,21,48,32) -> 24 | G23: =DATE(2026,1,1)+MOD((ROW()-12)*7,180) -> 46100 | H23: =G23+CHOOSE(MOD(ROW()-2,5)+1,90,120,150,180,210) -> 46220 | I23: =IF(MOD(ROW()-2,4)=0,"",H23+CHOOSE(MOD(ROW()-2,5)+1,-5,0,7,-2,10)) -> 46220 | J23: =IF(I23="","",I23-H23) -> 0 | K23: =CHOOSE(MOD(ROW()-2,6)+1,"Material Ordered","Material Delivered","Installation Started","Mechanical Completion","Testing & Commissioning","Handover") -> Mechanical Completion | L23: =IF(K23="Handover","Completed","In Progress") -> In Progress | M23: =IF(K23="Handover","Completed","Pending") -> Pending | N23: =IF(I23="","In Progress",IF(J23>0,"Delayed",IF(J23=0,"On Time","Early"))) -> On Time | P23: =COUNTIF($A$2:$A$306,A23) -> 1
A24: ="PRJ"&TEXT(ROW()-1,"000") -> PRJ023 | B24: =CHOOSE(MOD(ROW()-2,10)+1,"Green Valley","Royal Palm","Skyline","Harmony","Lakeside","Sunrise","Silver Oak","River View","Golden Gate","Emerald")&" "&CHOOSE(MOD(INT((ROW()-2)/10),8)+1,"Residency","Apartments","Heights","Towers","Enclave","Business Centre","Grand Hotel","Care Hospital")&" "&TEXT(ROW()-1,"000") -> Skyline Heights 023 | C24: =CHOOSE(MOD(ROW()-2,3)+1,"North Kerala","Central Kerala","South Kerala") -> Central Kerala | D24: =IF(C24="North Kerala",CHOOSE(MOD(ROW()-2,4)+1,"Kannur","Kozhikode","Wayanad","Kasaragod"),IF(C24="Central Kerala",CHOOSE(MOD(ROW()-2,6)+1,"Kochi","Thrissur","Kottayam","Palakkad","Idukki","Alappuzha"),CHOOSE(MOD(ROW()-2,4)+1,"Trivandrum","Kollam","Pathanamthitta","Alappuzha"))) -> Idukki | E24: =CHOOSE(MOD(ROW()-2,6)+1,"Residential","Apartment","Hospital","Office","Hotel","Commercial") -> Hotel | F24: =CHOOSE(MOD(ROW()-2,10)+1,18,24,42,65,38,55,27,21,48,32) -> 42 | G24: =DATE(2026,1,1)+MOD((ROW()-12)*7,180) -> 46107 | H24: =G24+CHOOSE(MOD(ROW()-2,5)+1,90,120,150,180,210) -> 46257 | I24: =IF(MOD(ROW()-2,4)=0,"",H24+CHOOSE(MOD(ROW()-2,5)+1,-5,0,7,-2,10)) -> 46264 | J24: =IF(I24="","",I24-H24) -> 7 | K24: =CHOOSE(MOD(ROW()-2,6)+1,"Material Ordered","Material Delivered","Installation Started","Mechanical Completion","Testing & Commissioning","Handover") -> Testing & Commissioning | L24: =IF(K24="Handover","Completed","In Progress") -> In Progress | M24: =IF(K24="Handover","Completed","Pending") -> Pending | N24: =IF(I24="","In Progress",IF(J24>0,"Delayed",IF(J24=0,"On Time","Early"))) -> Delayed | P24: =COUNTIF($A$2:$A$306,A24) -> 1
A25: ="PRJ"&TEXT(ROW()-1,"000") -> PRJ024 | B25: =CHOOSE(MOD(ROW()-2,10)+1,"Green Valley","Royal Palm","Skyline","Harmony","Lakeside","Sunrise","Silver Oak","River View","Golden Gate","Emerald")&" "&CHOOSE(MOD(INT((ROW()-2)/10),8)+1,"Residency","Apartments","Heights","Towers","Enclave","Business Centre","Grand Hotel","Care Hospital")&" "&TEXT(ROW()-1,"000") -> Harmony Heights 024 | C25: =CHOOSE(MOD(ROW()-2,3)+1,"North Kerala","Central Kerala","South Kerala") -> South Kerala | D25: =IF(C25="North Kerala",CHOOSE(MOD(ROW()-2,4)+1,"Kannur","Kozhikode","Wayanad","Kasaragod"),IF(C25="Central Kerala",CHOOSE(MOD(ROW()-2,6)+1,"Kochi","Thrissur","Kottayam","Palakkad","Idukki","Alappuzha"),CHOOSE(MOD(ROW()-2,4)+1,"Trivandrum","Kollam","Pathanamthitta","Alappuzha"))) -> Alappuzha | E25: =CHOOSE(MOD(ROW()-2,6)+1,"Residential","Apartment","Hospital","Office","Hotel","Commercial") -> Commercial | F25: =CHOOSE(MOD(ROW()-2,10)+1,18,24,42,65,38,55,27,21,48,32) -> 65 | G25: =DATE(2026,1,1)+MOD((ROW()-12)*7,180) -> 46114 | H25: =G25+CHOOSE(MOD(ROW()-2,5)+1,90,120,150,180,210) -> 46294 | I25: =IF(MOD(ROW()-2,4)=0,"",H25+CHOOSE(MOD(ROW()-2,5)+1,-5,0,7,-2,10)) -> 46292 | J25: =IF(I25="","",I25-H25) -> -2 | K25: =CHOOSE(MOD(ROW()-2,6)+1,"Material Ordered","Material Delivered","Installation Started","Mechanical Completion","Testing & Commissioning","Handover") -> Handover | L25: =IF(K25="Handover","Completed","In Progress") -> Completed | M25: =IF(K25="Handover","Completed","Pending") -> Completed | N25: =IF(I25="","In Progress",IF(J25>0,"Delayed",IF(J25=0,"On Time","Early"))) -> Early | P25: =COUNTIF($A$2:$A$306,A25) -> 1
A26: ="PRJ"&TEXT(ROW()-1,"000") -> PRJ025 | B26: =CHOOSE(MOD(ROW()-2,10)+1,"Green Valley","Royal Palm","Skyline","Harmony","Lakeside","Sunrise","Silver Oak","River View","Golden Gate","Emerald")&" "&CHOOSE(MOD(INT((ROW()-2)/10),8)+1,"Residency","Apartments","Heights","Towers","Enclave","Business Centre","Grand Hotel","Care Hospital")&" "&TEXT(ROW()-1,"000") -> Lakeside Heights 025 | C26: =CHOOSE(MOD(ROW()-2,3)+1,"North Kerala","Central Kerala","South Kerala") -> North Kerala | D26: =IF(C26="North Kerala",CHOOSE(MOD(ROW()-2,4)+1,"Kannur","Kozhikode","Wayanad","Kasaragod"),IF(C26="Central Kerala",CHOOSE(MOD(ROW()-2,6)+1,"Kochi","Thrissur","Kottayam","Palakkad","Idukki","Alappuzha"),CHOOSE(MOD(ROW()-2,4)+1,"Trivandrum","Kollam","Pathanamthitta","Alappuzha"))) -> Kannur | E26: =CHOOSE(MOD(ROW()-2,6)+1,"Residential","Apartment","Hospital","Office","Hotel","Commercial") -> Residential | F26: =CHOOSE(MOD(ROW()-2,10)+1,18,24,42,65,38,55,27,21,48,32) -> 38 | G26: =DATE(2026,1,1)+MOD((ROW()-12)*7,180) -> 46121 | H26: =G26+CHOOSE(MOD(ROW()-2,5)+1,90,120,150,180,210) -> 46331 | I26: =IF(MOD(ROW()-2,4)=0,"",H26+CHOOSE(MOD(ROW()-2,5)+1,-5,0,7,-2,10)) | J26: =IF(I26="","",I26-H26) | K26: =CHOOSE(MOD(ROW()-2,6)+1,"Material Ordered","Material Delivered","Installation Started","Mechanical Completion","Testing & Commissioning","Handover") -> Material Ordered | L26: =IF(K26="Handover","Completed","In Progress") -> In Progress | M26: =IF(K26="Handover","Completed","Pending") -> Pending | N26: =IF(I26="","In Progress",IF(J26>0,"Delayed",IF(J26=0,"On Time","Early"))) -> In Progress | P26: =COUNTIF($A$2:$A$306,A26) -> 1
A27: ="PRJ"&TEXT(ROW()-1,"000") -> PRJ026 | B27: =CHOOSE(MOD(ROW()-2,10)+1,"Green Valley","Royal Palm","Skyline","Harmony","Lakeside","Sunrise","Silver Oak","River View","Golden Gate","Emerald")&" "&CHOOSE(MOD(INT((ROW()-2)/10),8)+1,"Residency","Apartments","Heights","Towers","Enclave","Business Centre","Grand Hotel","Care Hospital")&" "&TEXT(ROW()-1,"000") -> Sunrise Heights 026 | C27: =CHOOSE(MOD(ROW()-2,3)+1,"North Kerala","Central Kerala","South Kerala") -> Central Kerala | D27: =IF(C27="North Kerala",CHOOSE(MOD(ROW()-2,4)+1,"Kannur","Kozhikode","Wayanad","Kasaragod"),IF(C27="Central Kerala",CHOOSE(MOD(ROW()-2,6)+1,"Kochi","Thrissur","Kottayam","Palakkad","Idukki","Alappuzha"),CHOOSE(MOD(ROW()-2,4)+1,"Trivandrum","Kollam","Pathanamthitta","Alappuzha"))) -> Thrissur | E27: =CHOOSE(MOD(ROW()-2,6)+1,"Residential","Apartment","Hospital","Office","Hotel","Commercial") -> Apartment | F27: =CHOOSE(MOD(ROW()-2,10)+1,18,24,42,65,38,55,27,21,48,32) -> 55 | G27: =DATE(2026,1,1)+MOD((ROW()-12)*7,180) -> 46128 | H27: =G27+CHOOSE(MOD(ROW()-2,5)+1,90,120,150,180,210) -> 46218 | I27: =IF(MOD(ROW()-2,4)=0,"",H27+CHOOSE(MOD(ROW()-2,5)+1,-5,0,7,-2,10)) -> 46213 | J27: =IF(I27="","",I27-H27) -> -5 | K27: =CHOOSE(MOD(ROW()-2,6)+1,"Material Ordered","Material Delivered","Installation Started","Mechanical Completion","Testing & Commissioning","Handover") -> Material Delivered | L27: =IF(K27="Handover","Completed","In Progress") -> In Progress | M27: =IF(K27="Handover","Completed","Pending") -> Pending | N27: =IF(I27="","In Progress",IF(J27>0,"Delayed",IF(J27=0,"On Time","Early"))) -> Early | P27: =COUNTIF($A$2:$A$306,A27) -> 1
A28: ="PRJ"&TEXT(ROW()-1,"000") -> PRJ027 | B28: =CHOOSE(MOD(ROW()-2,10)+1,"Green Valley","Royal Palm","Skyline","Harmony","Lakeside","Sunrise","Silver Oak","River View","Golden Gate","Emerald")&" "&CHOOSE(MOD(INT((ROW()-2)/10),8)+1,"Residency","Apartments","Heights","Towers","Enclave","Business Centre","Grand Hotel","Care Hospital")&" "&TEXT(ROW()-1,"000") -> Silver Oak Heights 027 | C28: =CHOOSE(MOD(ROW()-2,3)+1,"North Kerala","Central Kerala","South Kerala") -> South Kerala | D28: =IF(C28="North Kerala",CHOOSE(MOD(ROW()-2,4)+1,"Kannur","Kozhikode","Wayanad","Kasaragod"),IF(C28="Central Kerala",CHOOSE(MOD(ROW()-2,6)+1,"Kochi","Thrissur","Kottayam","Palakkad","Idukki","Alappuzha"),CHOOSE(MOD(ROW()-2,4)+1,"Trivandrum","Kollam","Pathanamthitta","Alappuzha"))) -> Pathanamthitta | E28: =CHOOSE(MOD(ROW()-2,6)+1,"Residential","Apartment","Hospital","Office","Hotel","Commercial") -> Hospital | F28: =CHOOSE(MOD(ROW()-2,10)+1,18,24,42,65,38,55,27,21,48,32) -> 27 | G28: =DATE(2026,1,1)+MOD((ROW()-12)*7,180) -> 46135 | H28: =G28+CHOOSE(MOD(ROW()-2,5)+1,90,120,150,180,210) -> 46255 | I28: =IF(MOD(ROW()-2,4)=0,"",H28+CHOOSE(MOD(ROW()-2,5)+1,-5,0,7,-2,10)) -> 46255 | J28: =IF(I28="","",I28-H28) -> 0 | K28: =CHOOSE(MOD(ROW()-2,6)+1,"Material Ordered","Material Delivered","Installation Started","Mechanical Completion","Testing & Commissioning","Handover") -> Installation Started | L28: =IF(K28="Handover","Completed","In Progress") -> In Progress | M28: =IF(K28="Handover","Completed","Pending") -> Pending | N28: =IF(I28="","In Progress",IF(J28>0,"Delayed",IF(J28=0,"On Time","Early"))) -> On Time | P28: =COUNTIF($A$2:$A$306,A28) -> 1
... A301: ="PRJ"&TEXT(ROW()-1,"000") -> PRJ300 | B301: =CHOOSE(MOD(ROW()-2,10)+1,"Green Valley","Royal Palm","Skyline","Harmony","Lakeside","Sunrise","Silver Oak","River View","Golden Gate","Emerald")&" "&CHOOSE(MOD(INT((ROW()-2)/10),8)+1,"Residency","Apartments","Heights","Towers","Enclave","Business Centre","Grand Hotel","Care Hospital")&" "&TEXT(ROW()-1,"000") -> Emerald Business Centre 300 | C301: =CHOOSE(MOD(ROW()-2,3)+1,"North Kerala","Central Kerala","South Kerala") -> South Kerala | D301: =IF(C301="North Kerala",CHOOSE(MOD(ROW()-2,4)+1,"Kannur","Kozhikode","Wayanad","Kasaragod"),IF(C301="Central Kerala",CHOOSE(MOD(ROW()-2,6)+1,"Kochi","Thrissur","Kottayam","Palakkad","Idukki","Alappuzha"),CHOOSE(MOD(ROW()-2,4)+1,"Trivandrum","Kollam","Pathanamthitta","Alappuzha"))) -> Alappuzha | E301: =CHOOSE(MOD(ROW()-2,6)+1,"Residential","Apartment","Hospital","Office","Hotel","Commercial") -> Commercial | F301: =CHOOSE(MOD(ROW()-2,10)+1,18,24,42,65,38,55,27,21,48,32) -> 32 | G301: =DATE(2026,1,1)+MOD((ROW()-12)*7,180) -> 46066 | H301: =G301+CHOOSE(MOD(ROW()-2,5)+1,90,120,150,180,210) -> 46276 | I301: =IF(MOD(ROW()-2,4)=0,"",H301+CHOOSE(MOD(ROW()-2,5)+1,-5,0,7,-2,10)) -> 46286 | J301: =IF(I301="","",I301-H301) -> 10 | K301: =CHOOSE(MOD(ROW()-2,6)+1,"Material Ordered","Material Delivered","Installation Started","Mechanical Completion","Testing & Commissioning","Handover") -> Handover | L301: =IF(K301="Handover","Completed","In Progress") -> Completed | M301: =IF(K301="Handover","Completed","Pending") -> Completed | N301: =IF(I301="","In Progress",IF(J301>0,"Delayed",IF(J301=0,"On Time","Early"))) -> Delayed | P301: =COUNTIF($A$2:$A$306,A301) -> 1
A302: PRJ301 | B302: Tech Park Tower 301 | C302: North Kerala | D302: Kozhikode | E302: Office | F302: 60 | G302: 46249 | H302: 46341 | I302: 46341 | J302: 0 | K302: Handover | L302: Completed | M302: Completed | N302: On Time | P302: =COUNTIF($A$2:$A$306,A302) -> 1
A303: PRJ302 | B303: Lake View Hospital 302 | C303: Central Kerala | D303: Ernakulam | E303: Hospital | F303: 72 | G303: 46254 | H303: 46376 | I303: 46383 | J303: 7 | K303: Testing & Commissioning | L303: Completed | M303: Completed | N303: Delayed | P303: =COUNTIF($A$2:$A$306,A303) -> 1
A304: PRJ303 | B304: Green Valley Hotel 303 | C304: South Kerala | D304: Alappuzha | E304: Hotel | F304: 45 | G304: 46266 | H304: 46371 | J304: -5 | K304: Installation Started | L304: In Progress | M304: Pending | N304: Early | P304: =COUNTIF($A$2:$A$306,A304) -> 1
A305: PRJ304 | B305: Sunrise Apartments 304 | C305: North Kerala | D305: Wayanad | E305: Residential | F305: 38 | G305: 46275 | H305: 46397 | J305: 10 | K305: Material Delivered | L305: In Progress | M305: Pending | N305: Delayed | P305: =COUNTIF($A$2:$A$306,A305) -> 1
A306: PRJ305 | B306: Metro Office Complex 305 | C306: Central Kerala | D306: Thrissur | E306: Commercial | F306: 55 | G306: 46283 | H306: 46374 | J306: 0 | K306: Material Ordered | L306: In Progress | M306: Pending | N306: On Time | P306: =COUNTIF($A$2:$A$306,A306) -> 1
A311: =COUNTIF($A$2:$A$306,"PRJ001") -> 1
A312: =MAX(COUNTIF($A$2:$A$306,$A$2:$A$306)) -> 0

Sheet Lists
A1: Region | B1: City | C1: Customer Type | D1: Installation Stage | E1: Status | F1: Handover Status
A2: North Kerala | B2: Kochi | C2: Residential | D2: Material Ordered | E2: On Track | F2: Pending
A3: Central Kerala | B3: Trivandrum | C3: Commercial | D3: Material Delivered | E3: Delayed | F3: Completed
A4: South Kerala | B4: Kozhikode | C4: Hospital | D4: Installation Started | E4: In Progress
B5: Thrissur | C5: Hotel | D5: Installation Completed | E5: Completed
B6: Kottayam | C6: Apartment | D6: Testing | E6: On Hold
B7: Kannur | C7: Office | D7: Inspection
B8: Palakkad | C8: Shopping Mall | D8: Handover
B9: Kollam
B10: Alappuzha
B11: Pathanamthitta
B12: Kasargod
B13: Wayanad

Sheet Pivot
A1: Row Labels | B1: Count of Project ID | D1: Row Labels | E1: Count of Project ID | H1: Row Labels | I1: Count of Project ID | L1: Row Labels | M1: Count of Project ID | O1: Row Labels | P1: Count of Project ID | S1: Row Labels | T1: Count of Project ID
A2: Central Kerala | B2: 105 | D2: Handover | E2: 57 | H2: Completed | I2: 58 | L2: Completed | M2: 58 | O2: Apartment | P2: 49 | S2: Alappuzha | T2: 26
A3: North Kerala | B3: 100 | D3: Installation Started | E3: 50 | H3: In Progress | I3: 247 | L3: Pending | M3: 247 | O3: Commercial | P3: 51 | S3: Idukki | T3: 49
A4: South Kerala | B4: 100 | D4: Material Delivered | E4: 50 | H4: Grand Total | I4: 305 | L4: Grand Total | M4: 305 | O4: Hospital | P4: 50 | S4: Kannur | T4: 25
A5: Grand Total | B5: 305 | D5: Material Ordered | E5: 50 | O5: Hotel | P5: 51 | S5: Kasaragod | T5: 24
D6: Mechanical Completion | E6: 48 | O6: Office | P6: 51 | S6: Kochi | T6: 5
D7: Testing & Commissioning | E7: 50 | O7: Residential | P7: 52 | S7: Kollam | T7: 25
D8: Grand Total | E8: 305 | O8: Shopping Mall | P8: 1 | S8: Kozhikode | T8: 26
O9: Grand Total | P9: 305 | S9: Pathanamthitta | T9: 24
S10: Thrissur | T10: 50
S11: Trivandrum | T11: 25
S12: Wayanad | T12: 25
S13: Ernakulam | T13: 1
S14: Grand Total | T14: 305
A31: Row Labels | B31: Count of Project ID
A32: Delayed | B32: 92
A33: Early | B33: 93 | E33: Average of Delay (Days)
A34: In Progress | B34: 75 | E34: 1.973913
A35: On Time | B35: 45
A36: Grand Total | B36: 305
E41: Sum of Project Value (₹ Lakhs)
E42: 11370
E46: Average of Project Value (₹ Lakhs)
E47: 37.278689
E50: Row Labels | F50: Sum of Project Value (₹ Lakhs) | H50: Row Labels | I50: Sum of Project Value (₹ Lakhs)
E51: Central Kerala | F51: 3992 | H51: Completed | I51: 2265
E52: North Kerala | F52: 3709 | H52: In Progress | I52: 9105
E53: South Kerala | F53: 3669 | H53: Grand Total | I53: 11370
E54: Grand Total | F54: 11370
A56: Row Labels | B56: Sum of Project Value (₹ Lakhs)
A57: Lake View Hospital 302 | B57: 72
A58: Harmony Grand Hotel 064 | B58: 65 | E58: Row Labels | F58: Sum of Project Value (₹ Lakhs)
A59: Harmony Residency 164 | B59: 65 | E59: Apartment | F59: 1949
A60: Harmony Heights 104 | B60: 65 | E60: Commercial | F60: 2002
A61: Harmony Apartments 094 | B61: 65 | E61: Hospital | F61: 1754
A62: Harmony Towers 194 | B62: 65 | E62: Hotel | F62: 1775
A63: Harmony Apartments 174 | B63: 65 | E63: Office | F63: 2046
A64: Harmony Grand Hotel 224 | B64: 65 | E64: Residential | F64: 1789
A65: Harmony Apartments 254 | B65: 65 | E65: Shopping Mall | F65: 55
A66: Harmony Heights 264 | B66: 65 | E66: Grand Total | F66: 11370
...

Sheet Dashboard
A1: PROJECT MONITORING DASHBOARD
A4: TOTAL PROJECTS | E4: COMPLETED | I4: IN PROGRESS | M4: HANDOVERS | Q4: DELAYED PROJECTS | U4: ON-TIME COMPLETION | Y4: AVERAGE DELAY | AC4: TOTAL PROJECT VALUE | AG4: AVERAGE PROJECT VALUE
A5: =IFERROR(GETPIVOTDATA("Count of Project ID",Pivot!$A$1),0) -> 305 | E5: =IFERROR(GETPIVOTDATA("Count of Project ID",Pivot!$H$1,"Status","Completed"),0) -> 58 | I5: =IFERROR(GETPIVOTDATA("Count of Project ID",Pivot!$H$1,"Status","In Progress"),0) -> 247 | M5: =IFERROR(GETPIVOTDATA("Count of Project ID",Pivot!$L$1,"Handover Status","Completed"),0) -> 58 | Q5: =IFERROR(GETPIVOTDATA("Count of Project ID",Pivot!$A$31,"Delay Status","Delayed"),0) -> 92 | U5: =IFERROR(GETPIVOTDATA("Count of Project ID",Pivot!$A$31,"Delay Status","On Time"),0) -> 45 | Y5: =IFERROR(GETPIVOTDATA("Average of Delay (Days)",Pivot!$E$33),0) -> 1.973913 | AC5: =GETPIVOTDATA("Project Value (₹ Lakhs)",Pivot!$E$41) -> 11370 | AG5: =GETPIVOTDATA("Project Value (₹ Lakhs)",Pivot!$E$46) -> 37.278689
AC9: HIGHEST VALUE PROJECT ANALYSIS
AC10: Highest Project Value : ₹65 Lakhs
AC11: Highest Value Projects : Multiple
A90: Region | B90: Status | C90: Customer Type
A91: North Kerala | B91: Completed | C91: Hospital
A92: Central Kerala | B92: In Progress | C92: Office
A93: North Kerala | B93: Completed | C93: Hotel
A94: South Kerala | B94: Completed | C94: Hospital
A95: North Kerala | B95: In Progress | C95: Apartment
A98: =COUNTIFS(B91:B95,"Completed",A91:A95,"North Kerala") -> 2 | B98: Answer | C98: Countifs | D98: North Kerala- Completed projects
A99: =COUNTIFS(B91:B95,"Completed",A91:A95,"North Kerala",C91:C95,"Hospital") -> 1 | B99: Answer | C99: Countifs | D99: Completed projects are there in North Kerala for the Hospital customer type
A102: Region | B102: Status | C102: Project Value
A103: North Kerala | B103: Completed | C103: 50
A104: North Kerala | B104: In Progress | C104: 65 | E104: =AVERAGEIF(B103:B106,"Completed",C103:C106) -> 48.333333 | F104: Averageif
A105: South Kerala | B105: Completed | C105: 40 | E105: =AVERAGEIFS(C103:C106,A103:A106,"North kerala",B103:B106,"Completed") -> 52.5 | F105: Averageifs
A106: North Kerala | B106: Completed | C106: 55 | E106: =AVERAGEIFS(C103:C106,B103:B106,"Completed",A103:A106,"South Kerala") -> 40 | F106: Averageifs
A109: =SUMIFS(C103:C106,A103:A106,"North Kerala",B103:B106,"Completed") -> 105 | B109: Sumifs | C109: total Project Value of Completed projects in North Kerala
A110: =SUMIFS(C103:C106,A103:A106,"North Kerala") -> 170 | B110: Sumifs | C110: total Project Value of projects in North Kerala, regardless of Status
A111: =SUMIF(B103:B106,"Completed",C103:C106) -> 145 | B111: Sumif
A113: Region | B113: Project Value
A114: North Kerala | B114: 50
A115: North Kerala | B115: 65
A116: South Kerala | B116: 40
A117: North Kerala | B117: 55
A119: =AVERAGEIF(A114:A117,"North Kerala",B114:B117) -> 56.666667 | B119: Averageif
A123: =IFERROR(100/0,0) -> 0 | B123: iferror
A125: Project Value | B125: Number of Projects
A126: 100 | B126: 5
A127: 200 | B127: 0 | C127: =IFERROR(A127/B127,0) -> 0 | D127: IFERROR
A131: Project ID | B131: Project Name | C131: Project Value
A132: PRJ001 | B132: Kochi Heights | C132: 50
A133: PRJ002 | B133: Metro Tower | C133: 65
A134: PRJ003 | B134: City Hospital | C134: 40
B136: =VLOOKUP("PRJ003",A131:C134,2,TRUE) -> City Hospital | C136: VLOKKUP
B137: =VLOOKUP("PRJ002",A131:C134,3,FALSE) -> 65 | C137: VLOKKUP
B139: =VLOOKUP("PRJ999",A131:C134,2,FALSE) -> #N/A
B140: =IFERROR(VLOOKUP("PRJ999",A131:C134,2,FALSE),"Not Found") -> Not Found
